[2021-02-14 19:01:06,488][asyncio][ERROR] - Future exception was never retrieved
future: <Future finished exception=KeyError("('<argenomic.mechanism.Descriptor object at 0x7f29a5-e2b419d0b5524f1904b30f83c87a203a', 53)")>
Traceback (most recent call last):
  File "/home/jonasver/anaconda3/envs/komorebi-develop/lib/python3.7/site-packages/distributed/client.py", line 1833, in _gather
    quiet_exceptions=AllExit,
  File "/home/jonasver/anaconda3/envs/komorebi-develop/lib/python3.7/site-packages/distributed/utils.py", line 230, in All
    result = await tasks.next()
  File "/home/jonasver/anaconda3/envs/komorebi-develop/lib/python3.7/site-packages/distributed/client.py", line 1822, in wait
    st = self.futures[k]
KeyError: "('<argenomic.mechanism.Descriptor object at 0x7f29a5-e2b419d0b5524f1904b30f83c87a203a', 117)"

During handling of the above exception, another exception occurred:

Traceback (most recent call last):
  File "/home/jonasver/anaconda3/envs/komorebi-develop/lib/python3.7/site-packages/tornado/gen.py", line 742, in run
    yielded = self.gen.throw(*exc_info)  # type: ignore
  File "/home/jonasver/anaconda3/envs/komorebi-develop/lib/python3.7/site-packages/distributed/utils.py", line 243, in quiet
    yield task
  File "/home/jonasver/anaconda3/envs/komorebi-develop/lib/python3.7/site-packages/tornado/gen.py", line 735, in run
    value = future.result()
  File "/home/jonasver/anaconda3/envs/komorebi-develop/lib/python3.7/site-packages/distributed/client.py", line 1822, in wait
    st = self.futures[k]
KeyError: "('<argenomic.mechanism.Descriptor object at 0x7f29a5-e2b419d0b5524f1904b30f83c87a203a', 53)"
