[2021-02-10 20:11:06,721][asyncio][ERROR] - Future exception was never retrieved
future: <Future finished exception=KeyError("('<styreman.mechanism.Descriptor object at 0x7ff0c4b-3d5b1151c4c426272947e105d9347239', 66)")>
Traceback (most recent call last):
  File "/home/jonasver/anaconda3/envs/komorebi-develop/lib/python3.7/site-packages/distributed/client.py", line 1833, in _gather
    quiet_exceptions=AllExit,
  File "/home/jonasver/anaconda3/envs/komorebi-develop/lib/python3.7/site-packages/distributed/utils.py", line 230, in All
    result = await tasks.next()
  File "/home/jonasver/anaconda3/envs/komorebi-develop/lib/python3.7/site-packages/distributed/client.py", line 1822, in wait
    st = self.futures[k]
KeyError: "('<styreman.mechanism.Descriptor object at 0x7ff0c4b-3d5b1151c4c426272947e105d9347239', 84)"

During handling of the above exception, another exception occurred:

Traceback (most recent call last):
  File "/home/jonasver/anaconda3/envs/komorebi-develop/lib/python3.7/site-packages/tornado/gen.py", line 742, in run
    yielded = self.gen.throw(*exc_info)  # type: ignore
  File "/home/jonasver/anaconda3/envs/komorebi-develop/lib/python3.7/site-packages/distributed/utils.py", line 243, in quiet
    yield task
  File "/home/jonasver/anaconda3/envs/komorebi-develop/lib/python3.7/site-packages/tornado/gen.py", line 735, in run
    value = future.result()
  File "/home/jonasver/anaconda3/envs/komorebi-develop/lib/python3.7/site-packages/distributed/client.py", line 1822, in wait
    st = self.futures[k]
KeyError: "('<styreman.mechanism.Descriptor object at 0x7ff0c4b-3d5b1151c4c426272947e105d9347239', 66)"
